tests/64_threads/sample_6.in
64
o
12 S 101 8 186 337
12 B 102 0 191 407
62 S 103 7 139 526
54 B 107 7 194 177
10 S 108 3 142 121
13 S 109 6 111 963
12 C 102
4 B 112 5 179 55
20 B 114 5 108 538
40 S 115 6 124 508
1 B 116 3 122 106
62 B 117 7 123 806
36 B 118 5 133 809
54 S 119 6 139 311
54 B 120 0 150 638
36 B 121 9 118 422
15 B 122 5 112 592
58 B 123 1 151 405
17 B 125 8 147 827
15 C 122
58 C 123
40 B 132 0 133 713
13 C 109
39 S 135 6 166 896
6 B 137 7 162 30
39 C 135
55 B 139 2 187 250
55 B 140 7 180 93
50 B 141 6 104 393
48 B 142 2 113 695
48 B 143 3 195 862
22 B 145 9 200 751
5 B 146 1 138 870
49 S 148 9 181 936
30 S 149 7 151 161
9 B 150 6 179 113
15 C 122
27 S 152 6 158 715
6 B 153 8 119 85
15 C 122
5 C 146
23 S 156 3 191 119
37 B 158 4 118 146
28 S 159 2 128 276
44 S 160 2 161 395
9 C 150
10 S 162 4 136 201
30 B 163 4 180 75
23 S 164 8 166 817
49 B 165 5 180 688
25 S 166 6 170 205
34 B 167 5 133 387
18 S 168 2 127 457
4 B 169 2 195 79
29 S 171 6 172 359
43 S 172 1 164 379
18 S 173 3 133 867
62 C 103
51 B 175 2 163 212
56 S 176 9 130 705
48 C 143
18 C 173
50 S 180 1 156 387
14 S 181 9 190 585
5 C 146
53 B 183 5 163 95
24 S 184 3 110 628
3 B 185 1 131 155
8 S 186 9 120 824
2 S 187 7 133 476
23 S 188 0 160 378
29 B 189 3 197 409
28 C 159
32 S 191 3 190 346
15 B 192 0 140 637
16 B 193 6 142 915
6 B 194 9 108 652
5 C 146
37 S 196 1 103 953
30 S 198 8 109 125
40 B 199 5 164 691
25 B 201 1 171 811
21 B 202 1 196 609
52 S 203 3 104 591
24 C 184
43 B 205 4 105 400
53 C 183
43 S 209 7 149 558
53 C 183
61 B 211 5 121 529
44 C 160
40 S 213 6 194 763
12 S 214 6 189 786
33 S 215 6 182 951
45 B 216 4 133 104
26 B 217 5 152 871
38 S 218 2 114 824
42 B 219 8 195 794
7 S 221 4 132 981
40 S 222 0 133 881
15 S 223 7 137 271
63 B 224 7 199 487
53 B 225 7 114 432
2 S 226 2 125 119
4 B 227 7 114 916
35 B 228 4 130 221
24 S 229 5 127 338
15 B 230 4 128 38
29 S 231 8 194 880
58 C 123
26 S 233 7 125 877
23 B 234 8 158 327
58 C 123
7 B 237 2 102 151
43 S 238 6 113 497
6 S 239 6 182 300
25 S 240 4 108 271
31 B 241 2 117 691
3 B 242 0 109 921
20 S 243 6 184 238
26 S 244 1 133 867
2 C 187
5 B 246 7 178 784
43 S 247 9 103 198
24 B 248 4 173 545
63 C 224
29 B 250 2 160 835
59 S 251 5 150 527
63 C 224
18 B 253 6 142 277
26 C 244
3 S 255 3 178 310
45 S 256 6 166 858
57 B 257 6 100 167
10 S 258 1 102 543
16 S 259 1 133 166
15 S 260 6 157 831
42 C 219
8 C 186
39 S 263 0 154 220
50 S 264 2 190 240
22 C 145
37 B 266 6 181 559
49 S 267 8 160 467
60 S 268 9 140 483
49 B 269 5 149 982
35 S 270 8 154 975
1 C 116
11 B 272 5 197 801
12 S 273 3 148 421
16 B 274 2 111 705
9 S 275 2 175 65
32 C 191
45 S 277 9 144 367
39 C 263
15 C 192
36 B 280 1 155 573
28 C 159
19 S 282 1 197 572
50 S 283 2 133 824
20 C 114
9 S 285 2 165 460
62 C 117
29 C 189
28 S 288 5 168 933
25 B 289 4 109 517
29 S 290 7 115 187
25 C 240
37 C 158
45 C 256
20 S 294 9 112 34
35 C 228
20 C 114
2 C 187
21 S 298 8 198 352
25 S 299 5 177 162
43 B 300 6 179 606
19 S 301 6 153 257
45 S 302 9 109 532
10 S 303 7 122 466
39 C 263
62 B 305 7 121 680
18 B 306 6 185 440
13 S 307 6 153 794
51 S 308 9 110 187
41 B 309 0 100 294
5 B 310 0 159 952
57 B 311 8 153 729
7 C 221
44 C 160
30 S 314 9 104 681
36 S 315 4 127 757
56 S 316 0 149 606
20 S 317 4 195 211
52 S 318 9 100 460
13 S 319 0 151 978
22 C 145
51 S 321 8 142 337
62 S 323 1 169 545
21 B 324 5 154 113
47 S 325 8 103 863
37 S 326 7 189 590
46 B 327 0 195 603
5 C 246
40 C 213
62 C 305
56 C 316
19 C 282
9 B 333 9 182 657
5 C 310
61 C 211
62 S 336 8 115 978
37 C 326
22 B 339 5 152 63
8 C 186
12 B 341 9 132 897
12 S 342 2 192 259
49 S 343 5 199 789
21 S 344 7 171 393
2 C 187
37 C 326
19 C 301
9 S 348 7 112 482
31 C 241
4 C 112
30 S 351 5 184 505
23 B 352 3 195 26
46 S 353 7 199 231
41 S 354 3 114 115
24 S 355 1 112 669
49 B 356 9 128 863
20 C 317
5 B 358 2 166 606
44 S 359 0 197 730
23 C 352
39 B 361 9 167 267
63 B 362 0 118 206
3 B 363 2 157 535
18 C 253
63 B 365 1 183 13
19 C 301
2 C 187
60 C 268
22 C 145
59 S 370 6 119 940
17 B 371 0 165 92
46 S 372 1 199 881
50 S 373 6 168 514
39 B 374 5 127 327
30 B 375 8 121 174
56 S 376 6 180 909
14 C 181
12 B 378 2 194 434
54 B 379 3 193 278
22 C 339
36 S 381 9 197 736
14 C 181
61 B 383 2 172 27
49 B 384 9 138 775
28 C 159
0 S 386 9 185 92
53 S 387 9 161 910
62 B 388 2 191 280
53 B 389 0 159 733
48 C 143
9 B 391 9 105 977
8 S 392 0 164 116
43 B 393 1 125 790
36 S 394 3 132 244
17 C 125
41 C 354
30 B 397 1 162 341
50 S 398 5 151 562
14 S 399 6 133 539
3 C 185
61 S 401 7 183 400
56 S 402 5 180 606
10 B 403 2 122 407
24 C 355
39 C 361
23 B 406 0 167 982
40 S 407 6 173 502
54 B 408 1 150 736
16 S 409 5 111 962
41 B 410 3 143 635
13 S 411 8 100 663
17 C 125
17 C 371
11 B 414 4 127 483
36 C 315
21 C 344
38 B 417 2 167 995
28 C 159
45 B 419 7 122 207
24 S 420 9 149 549
3 S 421 5 101 569
57 C 257
46 S 423 1 171 699
34 S 424 1 155 397
29 C 171
44 S 426 1 198 811
19 C 301
43 C 238
45 C 256
45 S 430 5 159 847
55 B 431 0 162 506
57 B 432 9 171 709
0 B 433 7 126 160
46 B 434 0 135 821
58 B 435 3 133 550
47 B 436 3 180 179
55 S 437 3 154 172
30 C 375
62 B 439 7 140 865
32 C 191
17 C 371
39 C 135
35 B 443 0 153 364
33 C 215
53 C 225
22 C 339
63 S 447 0 115 520
54 B 448 7 161 85
58 B 449 4 156 32
22 S 450 7 126 323
25 C 289
43 B 452 3 141 823
35 B 453 6 103 744
55 C 139
47 B 455 5 117 118
19 S 456 7 180 468
16 S 457 4 149 471
44 B 458 0 125 46
62 B 459 9 141 72
9 S 460 5 162 106
49 B 461 9 173 718
58 B 462 1 191 112
37 C 196
26 B 464 0 128 84
20 S 465 6 129 661
46 B 466 6 191 253
19 B 467 9 164 525
55 S 468 3 138 31
23 S 469 8 118 361
40 S 470 6 144 149
22 S 471 2 157 641
58 C 123
46 C 434
13 B 474 8 148 292
21 C 298
20 C 243
53 S 477 9 200 905
26 B 478 5 165 880
17 B 479 6 125 866
31 B 480 2 153 757
8 C 186
8 C 186
19 C 282
31 B 484 9 185 355
54 B 485 1 170 946
54 S 486 8 122 421
3 S 487 2 154 983
63 C 447
17 C 125
23 C 406
2 C 226
54 S 492 1 183 415
51 B 493 1 113 926
8 B 494 7 192 955
24 S 495 6 176 475
39 C 361
49 S 497 6 195 316
2 S 498 9 171 660
50 C 264
31 C 480
32 C 191
61 S 502 9 141 943
37 B 503 1 188 879
59 S 504 4 186 292
54 C 119
28 C 288
58 B 507 9 123 773
6 C 239
22 S 509 4 166 102
4 B 510 7 102 241
54 B 511 3 119 48
8 B 512 9 134 627
50 B 513 4 107 838
60 B 514 4 159 286
11 S 515 3 141 947
27 S 516 1 125 495
27 C 516
16 S 518 1 193 663
56 B 519 4 161 254
12 S 520 5 184 906
50 S 521 2 100 597
15 C 192
30 B 523 3 192 806
39 C 263
28 S 525 7 127 981
7 C 221
37 S 527 1 168 911
49 C 497
5 B 529 7 128 812
57 C 311
5 B 531 3 148 891
58 B 532 4 123 669
36 B 533 8 159 624
42 C 219
27 C 152
45 S 536 9 127 83
32 S 537 3 197 696
35 S 538 2 172 131
22 S 539 4 158 662
12 B 540 8 185 796
32 S 541 4 123 407
37 C 158
54 C 485
33 B 544 0 145 129
47 S 545 8 121 683
30 S 546 2 180 252
63 C 447
49 C 343
42 S 549 9 166 332
42 S 550 2 108 217
14 S 551 2 110 112
17 C 125
11 S 553 9 126 780
0 S 554 8 102 682
55 B 555 2 134 111
34 C 424
49 B 557 1 200 401
45 B 558 3 126 35
1 S 559 4 174 818
1 S 560 0 131 701
56 S 561 3 192 798
48 B 562 0 120 197
49 C 384
24 S 564 5 183 166
15 C 223
8 C 512
32 C 541
8 S 568 9 127 117
62 S 569 7 155 10
59 C 251
40 C 199
43 B 572 9 118 18
5 C 529
59 C 251
8 B 575 4 159 332
46 C 423
14 B 577 1 149 69
2 S 578 9 199 849
40 C 407
6 C 153
32 S 581 3 138 90
0 C 386
42 B 583 5 175 763
54 C 448
43 S 585 6 157 684
3 C 421
59 B 587 8 154 766
7 S 588 1 124 865
11 B 589 0 142 28
18 B 590 2 181 577
15 C 260
62 S 592 1 108 830
22 C 339
63 C 365
20 S 595 9 171 734
54 B 596 2 127 402
49 S 597 7 110 578
26 B 598 2 130 890
30 C 149
32 S 600 5 185 190
29 S 601 0 167 883
23 S 602 1 112 103
13 S 603 1 198 647
9 C 348
55 C 431
41 S 606 5 182 577
31 S 607 2 176 560
44 C 160
60 S 609 2 139 792
33 C 215
24 S 611 0 196 278
15 C 192
13 C 474
29 S 614 0 198 486
30 C 149
47 C 545
63 B 617 4 136 177
62 B 618 1 111 453
23 S 619 0 106 326
8 B 620 8 190 711
63 C 617
24 S 622 2 158 145
7 S 623 3 147 131
63 S 624 7 149 697
39 S 625 4 117 46
28 C 159
8 B 627 1 178 442
7 S 628 4 113 887
41 S 629 4 115 431
26 B 630 6 166 34
58 C 462
36 S 632 8 161 944
14 S 633 0 123 66
12 S 634 0 102 98
45 C 216
19 S 636 4 120 821
