tests/64_threads/sample_60.in
64
o
29 B 101 3 101 897
7 S 102 3 163 120
28 B 104 8 173 731
5 B 106 0 132 725
24 S 107 8 132 635
27 B 108 9 120 809
24 S 109 2 112 957
47 B 110 5 102 348
55 B 112 3 110 577
30 B 113 1 144 158
40 B 115 2 161 238
29 S 116 9 114 369
56 B 117 8 100 586
52 S 118 4 193 744
21 S 120 4 146 589
30 S 121 9 103 566
56 B 123 1 188 600
20 B 124 5 132 213
43 B 126 6 179 353
27 S 127 3 170 619
41 B 128 7 133 908
40 B 129 7 120 120
45 B 130 4 119 11
1 S 131 7 155 721
24 B 132 2 110 885
22 B 133 1 148 337
63 B 134 8 111 479
14 B 135 5 136 291
1 C 131
20 S 137 3 195 267
13 S 138 4 125 626
36 B 140 6 132 440
51 B 142 6 124 205
0 S 143 9 139 134
54 B 144 9 179 256
54 C 144
54 S 147 8 124 559
39 B 148 2 143 412
6 S 149 7 131 996
54 S 150 7 177 10
40 C 115
47 B 152 2 147 423
43 C 126
21 C 120
50 B 155 9 161 645
23 B 156 9 141 922
25 B 157 1 106 322
20 C 137
32 S 160 2 165 269
14 B 161 2 127 370
1 C 131
63 B 164 6 104 647
62 S 165 0 185 894
29 B 166 1 100 840
54 B 167 6 113 614
52 B 168 3 198 99
15 B 169 3 165 956
60 S 170 5 134 988
56 C 123
41 S 172 2 147 270
28 S 174 3 128 571
38 B 175 4 178 557
29 C 166
41 B 177 4 200 490
39 B 178 2 134 388
47 C 152
62 C 165
36 B 181 4 133 273
40 C 129
31 S 183 1 134 914
12 S 184 1 170 692
30 S 185 0 154 362
30 S 186 9 164 934
48 B 187 4 151 177
13 B 190 7 128 971
50 S 191 7 189 588
47 S 192 2 181 932
23 S 193 3 128 469
23 S 194 7 114 540
63 C 134
49 B 197 8 161 994
0 B 198 2 159 394
28 B 200 4 128 695
35 S 201 7 121 15
58 B 202 3 197 387
45 C 130
1 B 204 6 149 875
15 S 206 3 162 555
6 C 149
14 C 161
3 S 210 8 110 712
49 B 212 1 142 850
42 B 213 6 188 560
14 S 214 9 176 532
14 C 161
42 C 213
24 C 107
38 B 218 5 121 583
55 S 219 9 106 872
13 S 221 7 142 12
16 B 222 4 183 721
14 S 224 7 144 320
59 B 226 3 177 739
23 S 227 2 123 786
24 C 132
30 B 229 8 158 149
53 S 230 9 132 769
41 S 231 9 191 841
11 S 232 3 152 858
60 C 170
28 B 234 3 163 161
12 C 184
49 B 236 1 182 404
21 S 237 3 171 120
45 B 238 2 169 116
10 B 239 1 192 711
19 B 240 5 148 375
28 B 241 3 194 372
51 B 242 9 110 93
10 S 243 8 131 982
6 C 149
53 S 245 7 191 15
50 C 191
43 S 248 2 157 870
50 B 249 5 131 174
6 B 250 9 198 16
46 S 252 7 111 88
13 C 221
35 B 254 0 169 144
52 B 255 0 140 860
3 B 256 1 121 757
48 B 257 6 118 420
7 B 258 4 103 309
42 B 259 6 175 318
15 B 260 1 124 243
6 S 261 2 165 72
47 S 262 5 173 468
49 C 236
63 S 264 6 192 588
7 B 265 9 136 733
22 B 266 0 110 876
16 C 222
1 S 268 0 144 576
58 S 269 0 146 340
39 S 270 1 159 183
5 S 271 0 157 496
22 B 272 6 106 553
63 B 273 6 161 398
19 S 274 2 171 611
5 S 275 6 118 209
46 B 276 4 118 145
55 S 277 1 148 793
30 C 113
9 B 279 5 152 220
36 C 140
62 C 165
18 S 282 0 199 824
47 C 262
36 S 284 5 104 589
47 C 192
48 C 257
21 S 287 7 121 198
5 B 288 7 157 217
63 S 289 5 199 465
13 S 290 3 122 662
30 B 291 2 184 740
19 S 292 9 114 99
52 B 293 4 110 638
18 B 294 6 105 465
0 C 143
34 B 296 4 140 157
1 B 297 8 184 570
16 C 222
37 S 300 7 147 510
1 C 204
37 C 300
53 S 303 7 195 348
24 C 132
23 B 305 2 160 975
58 B 306 7 142 962
52 B 307 9 155 970
44 B 308 2 196 808
63 C 134
5 S 310 3 102 462
51 B 311 6 143 229
59 B 312 3 182 336
15 C 260
1 S 314 8 136 687
52 B 315 7 169 867
36 S 316 2 123 922
44 S 317 3 169 249
23 C 156
20 S 319 5 135 624
20 C 319
18 C 294
22 B 323 3 130 347
59 B 324 9 104 261
30 B 325 9 138 307
37 S 327 0 175 169
22 S 328 4 138 825
5 S 329 8 128 382
34 C 296
37 S 331 6 158 118
14 B 332 4 148 990
37 C 300
9 B 334 3 188 28
26 B 335 0 118 733
6 B 336 1 173 482
3 C 256
40 C 129
12 B 339 7 171 880
7 C 258
51 S 341 5 118 739
24 S 342 4 197 655
55 B 343 2 116 341
32 S 344 9 107 542
11 S 345 2 161 270
4 B 346 9 148 423
8 S 347 2 108 705
36 S 348 8 134 27
0 S 349 6 142 918
31 S 350 9 179 449
7 C 265
38 C 175
29 B 353 7 101 765
0 C 349
41 B 355 7 135 398
32 C 160
18 B 357 4 140 376
9 B 358 7 196 110
4 C 346
50 B 360 2 114 806
2 S 361 9 156 184
14 C 135
51 B 363 6 152 820
24 B 364 6 170 856
51 B 365 1 139 23
42 S 366 1 193 621
26 B 367 7 161 714
52 B 368 1 140 294
20 C 124
15 S 370 2 153 566
24 S 371 2 126 520
6 S 372 2 179 714
37 C 331
18 S 374 0 186 828
22 S 375 2 113 212
6 C 149
6 S 377 6 134 805
16 C 222
2 S 379 9 122 439
26 S 380 0 152 865
62 C 165
11 C 232
45 S 383 6 137 264
18 C 282
38 S 385 8 104 327
28 S 386 8 129 58
18 B 387 2 161 716
48 C 187
10 C 239
9 C 358
27 B 391 3 181 547
53 C 303
60 S 393 4 176 759
49 C 236
11 B 395 8 109 395
63 C 289
6 B 397 3 132 363
8 B 398 4 139 424
4 S 399 5 125 481
50 B 400 1 100 118
51 C 341
25 B 402 5 114 775
21 C 120
45 B 404 6 129 132
2 S 405 3 159 777
0 S 406 5 123 324
51 S 408 3 108 185
13 B 409 5 186 900
6 B 410 3 116 154
35 C 254
30 S 412 3 197 791
38 B 413 2 195 730
26 S 414 5 136 177
56 B 415 4 185 168
26 S 416 0 180 565
22 S 417 3 114 893
9 C 279
47 C 152
13 B 420 3 130 459
16 B 421 2 114 88
36 C 348
26 S 423 4 139 334
8 B 424 8 137 600
44 B 425 3 127 174
37 B 426 1 132 184
44 C 317
16 B 428 7 187 219
60 C 393
2 B 430 2 141 607
37 C 300
26 S 432 3 111 57
28 B 433 8 189 427
30 C 291
21 B 435 5 113 163
9 C 279
60 C 393
17 B 438 5 121 883
55 S 439 8 163 75
32 C 160
42 S 441 1 162 587
11 S 442 6 124 690
8 S 443 5 122 569
40 C 115
3 S 445 5 157 787
55 S 446 7 152 609
43 B 447 0 191 884
34 C 296
55 S 449 7 187 469
47 B 450 2 191 763
42 S 451 5 165 863
9 S 452 0 111 869
38 C 413
12 C 339
46 B 455 9 178 78
41 C 231
44 B 457 3 136 137
47 S 458 6 196 961
11 S 459 9 126 903
31 C 183
38 C 385
10 C 243
19 C 292
30 S 464 6 146 704
45 C 238
22 S 466 5 119 701
50 S 467 7 136 927
32 C 344
6 C 397
39 C 178
45 S 471 6 104 442
20 S 472 1 156 837
25 B 473 3 169 691
4 C 346
62 S 475 0 107 379
49 S 476 6 104 275
19 C 240
48 S 478 9 108 764
17 B 479 4 159 981
44 S 480 7 126 82
21 S 481 5 102 137
52 S 482 6 130 167
34 C 296
58 B 484 1 191 849
9 C 334
7 B 486 5 183 154
60 B 487 6 129 285
26 S 488 4 162 143
15 B 489 2 159 457
49 C 476
36 B 491 3 153 265
41 S 492 4 198 24
43 B 493 8 146 99
36 B 494 8 163 774
16 C 428
18 S 496 4 138 473
40 S 497 3 125 182
49 S 498 0 179 714
23 C 193
4 B 500 7 110 374
41 C 172
62 B 502 6 146 423
48 B 503 2 170 710
18 S 504 1 158 559
34 S 505 6 137 844
23 B 506 7 120 750
6 S 507 9 177 781
21 B 508 2 141 881
17 B 509 4 128 120
44 S 510 6 104 322
38 C 175
28 C 200
17 B 513 4 168 72
62 C 165
36 S 515 3 143 171
30 B 516 2 180 247
21 C 481
29 S 519 6 106 159
40 S 520 9 150 405
44 B 521 7 139 893
10 S 522 6 192 61
63 S 523 9 157 434
39 S 524 3 126 320
35 C 201
37 C 327
44 B 527 2 106 760
53 S 528 1 150 164
52 C 293
18 S 530 4 130 370
8 C 424
55 C 112
30 C 121
51 B 534 3 103 684
48 S 535 5 178 589
9 S 536 1 172 636
8 C 443
51 B 538 1 102 461
51 B 539 7 179 688
63 B 540 5 196 304
10 S 541 5 170 268
47 C 110
17 B 543 0 178 151
58 B 544 5 105 700
6 S 545 2 183 546
2 S 546 2 185 545
39 S 547 8 200 93
8 S 548 3 118 634
43 C 126
29 C 101
24 B 551 2 119 996
17 B 552 0 193 609
0 C 198
49 C 212
35 B 555 6 114 744
29 B 556 2 154 244
38 S 557 3 129 643
18 C 504
7 C 258
13 C 409
9 C 536
51 S 562 3 100 144
44 C 317
20 C 137
22 S 565 4 139 699
3 S 566 9 178 256
26 B 567 4 134 863
56 S 568 7 155 880
16 B 569 9 144 995
37 C 331
50 B 571 0 102 767
47 B 572 2 154 256
32 C 160
2 B 574 4 100 578
12 C 339
4 S 576 2 194 541
0 B 577 0 198 365
51 B 578 4 157 216
62 B 579 7 124 564
4 C 346
41 S 581 0 159 114
12 C 184
39 S 583 4 134 901
62 B 584 7 158 536
20 C 137
52 C 255
30 C 325
41 S 588 6 167 197
54 C 144
35 B 590 0 113 788
43 S 591 5 114 81
25 B 592 7 174 593
7 B 593 9 154 102
24 C 109
20 S 595 3 172 613
7 B 596 5 184 380
52 C 118
47 S 598 9 139 261
50 C 571
31 B 600 4 101 176
22 C 266
9 C 536
13 C 409
45 S 604 7 116 205
52 C 307
48 S 606 6 112 396
25 C 592
37 B 608 0 127 598
41 C 172
33 S 610 0 125 136
8 S 611 1 125 354
60 C 170
38 S 613 0 128 125
48 C 187
58 S 615 7 130 650
43 C 493
20 C 124
2 B 618 5 105 631
49 B 619 7 165 151
23 S 620 7 193 818
37 C 300
63 S 622 7 103 660
57 S 623 2 183 149
60 B 624 6 137 771
36 S 625 5 191 296
19 C 274
6 B 627 6 150 249
22 S 628 8 121 653
59 S 629 7 194 25
11 C 442
25 C 473
61 B 633 7 176 383
47 S 634 6 138 699
28 S 635 6 137 653
36 C 348
33 S 637 2 191 676
